<?xml version="1.0"?>
<robot name="robot">
  <material name="black">
    <color rgba="0 0 0 1"/>
  </material>
  <material name="pink">
    <color rgba="1.0 0.412 0.706 1"/>
  </material>
  <material name="green">
    <color rgba="0 1 0 1"/>
  </material>
  <material name="red">
    <color rgba="1 0 0 1"/>
  </material>
  <material name="blue">
    <color rgba="0 0 1 1"/>
  </material>
  <material name="gray">
    <color rgba="0.502 0.502 0.502 1"/>
  </material>
  <material name="white">
    <color rgba="1 1 1 1"/>
  </material>


    <gazebo>
        <plugin name="gazebo_ros_control" filename="libgazebo_ros_control.so">
            <robotNamespace>/robot</robotNamespace>
        </plugin>
    </gazebo>

    <gazebo reference="base">
      <material>Gazebo/Black</material>
    </gazebo>


    <link name="base">
      <visual>
        <geometry>
           <box size="1.5 1 0.125"/>
        </geometry>
        <origin rpy="0 0 0" xyz="0 0 0"/>
        <material name="black"/>
      </visual>
      <inertial>
        <mass value="5"/>
        <origin rpy="0 0 0" xyz="0 0 0"/>
        <inertia ixx="0.9440104167" ixy="0" ixz="0" iyy="0.4231770833" iyz="0" izz="1.354166666"/>
      </inertial>
      <collision>
        <geometry>
          <box size="1.5 1 0.125"/>
        </geometry>
      </collision>
    </link>

    <gazebo reference="right_wheel_motor">
      <material>Gazebo/Grey</material>
    </gazebo>

    <link name="right_wheel_motor">
      <visual>
        <geometry>
           <box size="0.25 0.25 0.15"/>
        </geometry>
        <origin rpy="0 0 0" xyz="0 0 0"/>
        <material name="gray"/>
      </visual>
      <inertial>
        <mass value="1"/>
        <origin rpy="0 0 0" xyz="0 0 0"/>
        <inertia ixx="0.007083333333" ixy="0" ixz="0" iyy="0.00708333333" iyz="0" izz="0.010416666666"/>
      </inertial>
      <collision>
        <geometry>
           <box size="0.25 0.25 0.15"/>
        </geometry>
      </collision>
    </link>

  <gazebo reference="left_wheel_motor">
    <material>Gazebo/Grey</material>
  </gazebo>

    <link name="left_wheel_motor">
      <visual>
        <geometry>
           <box size="0.25 0.25 0.15"/>
        </geometry>
        <origin rpy="0 0 0" xyz="0 0 0"/>
        <material name="gray"/>
      </visual>
      <inertial>
        <mass value="0.2"/>
        <origin rpy="0 0 0" xyz="0 0 0"/>
        <inertia ixx="0.007083333333" ixy="0" ixz="0" iyy="0.00708333333" iyz="0" izz="0.010416666666"/>
      </inertial>
      <collision>
        <geometry>
           <box size="0.25 0.25 0.15"/>
        </geometry>
      </collision>
    </link>

    <gazebo reference="left_wheel">
      <material>Gazebo/Black</material>
    </gazebo>

    <link name="left_wheel">
      <visual>
        <geometry>
          <cylinder length="0.1" radius="0.2"/>
        </geometry>
        <origin rpy="1.5707 0 0" xyz="0 0 0"/>
        <material name="black"/>
      </visual>
      <inertial>
        <mass value="0.75"/>
        <origin rpy="1.5707 0 0" xyz="0 0 0"/>
        <inertia ixx="0.0008125" ixy="0" ixz="0" iyy="0.0008125" iyz="0" izz="0.015"/>
      </inertial>
      <collision>
        <origin rpy="1.5707 0 0" xyz="0 0 0"/>
        <geometry>
          <cylinder length="0.1" radius="0.2"/>
        </geometry>
      </collision>
    </link>

    <gazebo reference="right_wheel">
      <material>Gazebo/Black</material>
    </gazebo>

    <link name="right_wheel">
      <visual>
        <geometry>
          <cylinder length="0.1" radius="0.2"/>
        </geometry>
        <origin rpy="1.5707 0 0" xyz="0 0 0"/>
        <material name="black"/>
      </visual>
      <inertial>
        <mass value="0.75"/>
        <origin rpy="1.5707 0 0" xyz="0 0 0"/>
        <inertia ixx="0.0008125" ixy="0" ixz="0" iyy="0.0008125" iyz="0" izz="0.015"/>
      </inertial>
      <collision>
        <origin rpy="1.5707 0 0" xyz="0 0 0"/>
        <geometry>
          <cylinder length="0.1" radius="0.2"/>
        </geometry>
      </collision>
    </link>

    <gazebo reference="right_wheel_spin_indicator">
      <material>Gazebo/Purple</material>
    </gazebo>

    <link name="right_wheel_spin_indicator">
      <visual>
        <geometry>
          <box size="0.05 0.05 0.05"/>
        </geometry>
        <origin rpy="1.5707 0 0" xyz="0 0 0"/>
        <material name="pink"/>
      </visual>
      <inertial>
        <mass value="0.1"/>
        <origin rpy="1.5707 0 0" xyz="0 0 0"/>
        <inertia ixx="0.000041666666" ixy="0" ixz="0" iyy="0.000041666666" iyz="0" izz="0.000041666666"/>
      </inertial>
      <collision>
        <origin rpy="1.5707 0 0" xyz="0 0 0"/>
        <geometry>
          <box size="0.05 0.05 0.05"/>
        </geometry>
      </collision>
    </link>

    <gazebo reference="left_wheel_spin_indicator">
      <material>Gazebo/Purple</material>
    </gazebo>

    <link name="left_wheel_spin_indicator">
      <visual>
        <geometry>
          <box size="0.05 0.05 0.05"/>
        </geometry>
        <origin rpy="1.5707 0 0" xyz="0 0 0"/>
        <material name="pink"/>
      </visual>
      <inertial>
        <mass value="0.2"/>
        <origin rpy="1.5707 0 0" xyz="0 0 0"/>
        <inertia ixx="0.000041666666" ixy="0" ixz="0" iyy="0.000041666666" iyz="0" izz="0.000041666666"/>
      </inertial>
      <collision>
        <origin rpy="1.5707 0 0" xyz="0 0 0"/>
        <geometry>
          <box size="0.05 0.05 0.05"/>
        </geometry>
      </collision>
    </link>

    <gazebo reference="left_wheel_axel">
      <material>Gazebo/Blue</material>
    </gazebo>

    <link name="left_wheel_axel">
      <visual>
        <geometry>
          <cylinder length="0.2" radius="0.05"/>
        </geometry>
        <origin rpy="1.5707 0 0" xyz="0 0 0"/>
        <material name="blue"/>
      </visual>
      <inertial>
        <mass value="0.2"/>
        <origin rpy="1.5707 0 0" xyz="0 0 0"/>
        <inertia ixx="0.0007916666666" ixy="0" ixz="0" iyy="0.0007916666666" iyz="0" izz="0.00025"/>
      </inertial>
      <collision>
        <origin rpy="1.5707 0 0" xyz="0 0 0"/>
        <geometry>
          <cylinder length="0.2" radius="0.05"/>
        </geometry>
      </collision>
    </link>

    <gazebo reference="right_wheel_axel">
      <material>Gazebo/Blue</material>
    </gazebo>

    <link name="right_wheel_axel">
      <visual>
        <geometry>
          <cylinder length="0.2" radius="0.05"/>
        </geometry>
        <origin rpy="1.5707 0 0" xyz="0 0 0"/>
        <material name="blue"/>
      </visual>
      <inertial>
        <mass value="0.2"/>
        <origin rpy="1.5707 0 0" xyz="0 0 0"/>
        <inertia ixx="0.0007916666666" ixy="0" ixz="0" iyy="0.0007916666666" iyz="0" izz="0.00025"/>
      </inertial>
      <collision>
        <origin rpy="1.5707 0 0" xyz="0 0 0"/>
        <geometry>
          <cylinder length="0.2" radius="0.05"/>
        </geometry>
      </collision>
    </link>

    <gazebo reference="left_caster_shaft">
      <material>Gazebo/Black</material>
    </gazebo>

    <link name="left_caster_shaft">
      <visual>
        <geometry>
          <cylinder length="0.3" radius="0.0375"/>
        </geometry>
        <origin rpy="0 0 0" xyz="0 0 0"/>
        <material name="black"/>
      </visual>
      <inertial>
        <mass value="0.2"/>
        <origin rpy="0 0 0" xyz="0 0 0"/>
        <inertia ixx="0.001570312499999" ixy="0" ixz="0" iyy="0.001570312499999" iyz="0" izz="0.000140625"/>
      </inertial>
      <collision>
        <geometry>
          <cylinder length="0.3" radius="0.0375"/>
        </geometry>
      </collision>
    </link>

    <gazebo reference="right_caster_shaft">
      <material>Gazebo/Black</material>
    </gazebo>

    <link name="right_caster_shaft">
      <visual>
        <geometry>
          <cylinder length="0.3" radius="0.0375"/>
        </geometry>
        <origin rpy="0 0 0" xyz="0 0 0"/>
        <material name="black"/>
      </visual>
      <inertial>
        <mass value="0.2"/>
        <origin rpy="0 0 0" xyz="0 0 0"/>
        <inertia ixx="0.001570312499999" ixy="0" ixz="0" iyy="0.001570312499999" iyz="0" izz="0.000140625"/>
      </inertial>
      <collision>
        <geometry>
          <cylinder length="0.3" radius="0.0375"/>
        </geometry>
      </collision>
    </link>

      <gazebo reference="left_caster_ball">
        <material>Gazebo/White</material>
      </gazebo>

      <link name="left_caster_ball">
      <visual>
        <geometry>
          <sphere radius="0.0375"/>
        </geometry>
        <origin rpy="0 0 0" xyz="0 0 0"/>
        <material name="white"/>
      </visual>
      <inertial>
        <mass value="0.3"/>
        <origin rpy="0 0 0" xyz="0 0 0"/>
        <inertia ixx="0.00016875" ixy="0" ixz="0" iyy="0.00016875" iyz="0" izz="0.00016875"/>
      </inertial>
      <collision>
        <geometry>
          <sphere radius="0.0375"/>
        </geometry>
      </collision>
    </link>

    <gazebo reference="right_caster_ball">
      <material>Gazebo/White</material>
    </gazebo>

    <link name="right_caster_ball">
      <visual>
        <geometry>
          <sphere radius="0.0375"/>
        </geometry>
        <origin rpy="0 0 0" xyz="0 0 0"/>
        <material name="white"/>
      </visual>
      <inertial>
        <mass value="0.3"/>
        <origin rpy="0 0 0" xyz="0 0 0"/>
        <inertia ixx="0.00016875" ixy="0" ixz="0" iyy="0.00016875" iyz="0" izz="0.00016875"/>
      </inertial>
      <collision>
        <geometry>
          <sphere radius="0.0375"/>
        </geometry>
      </collision>
    </link>

    <gazebo reference="screen_mount">
      <material>Gazebo/Grey</material>
    </gazebo>

     <link name="screen_mount">
      <visual>
        <geometry>
          <cylinder length="0.5" radius="0.08"/>
        </geometry>
        <origin rpy="0 0 0" xyz="0 0 0"/>
        <material name="gray"/>
      </visual>
      <inertial>
        <mass value="0.5"/>
        <origin rpy="0 0 0" xyz="0 0 0"/>
        <inertia ixx="0.0112166666" ixy="0" ixz="0" iyy="0.0112166666" iyz="0" izz="0.0016"/>
      </inertial>
      <collision>
        <geometry>
          <cylinder length="0.5" radius="0.08"/>
        </geometry>
      </collision>
    </link>

    <gazebo reference="screen">
      <material>Gazebo/Black</material>
    </gazebo>

    <link name="screen">
      <visual>
        <geometry>
          <box size="0.5 1 0.125"/>
        </geometry>
        <origin rpy="0 -0.7853 0" xyz="0 0 0"/>
        <material name="black"/>
      </visual>
      <inertial>
        <mass value="1"/>
        <origin rpy="0 -0.7853 0" xyz="0 0 0"/>
        <inertia ixx="0.02213541666666" ixy="0" ixz="0" iyy="0.08463541666666" iyz="0" izz="0.10416666666666"/>
      </inertial>
      <collision>
        <origin rpy="0 -0.7853 0" xyz="0 0 0"/>
        <geometry>
          <box size="0.5 1 0.125"/>
        </geometry>
      </collision>

    </link>

    <gazebo reference="computer_baseplate">
      <material>Gazebo/Red</material>
    </gazebo>

    <link name="computer_baseplate">
      <visual>
        <geometry>
          <box size="0.4 0.5 0.03"/>
        </geometry>
        <origin rpy="0 0 0" xyz="0 0 0"/>
        <material name="red"/>
      </visual>
      <inertial>
        <mass value="0.5"/>
        <origin rpy="0 0 0" xyz="0 0 0"/>
        <inertia ixx="0.00670416666" ixy="0" ixz="0" iyy="0.010454166666" iyz="0" izz="0.0170833333333"/>
      </inertial>
      <collision>
        <geometry>
          <box size="0.4 0.5 0.03"/>
        </geometry>
      </collision>

    </link>

    <gazebo reference="board_low">
      <material>Gazebo/Green</material>
    </gazebo>

    <link name="board_low">
      <visual>
        <geometry>
          <box size="0.3 0.375 0.03"/>
        </geometry>
        <origin rpy="0 0 0" xyz="0 0 0"/>
        <material name="green"/>
      </visual>
      <inertial>
        <mass value="0.4"/>
        <origin rpy="0 0 0" xyz="0 0 0"/>
        <inertia ixx="0.003020299" ixy="0" ixz="0" iyy="0.0047175" iyz="0" izz="0.0076875"/>
      </inertial>
       <collision>
        <geometry>
          <box size="0.3 0.375 0.03"/>
        </geometry>
      </collision>
   </link>

    <gazebo reference="board_high">
      <material>Gazebo/Green</material>
    </gazebo>

    <link name="board_high">
      <visual>
        <geometry>
          <box size="0.3 0.375 0.03"/>
        </geometry>
        <origin rpy="0 0 0" xyz="0 0 0"/>
        <material name="green"/>
      </visual>
      <inertial>
        <mass value="0.4"/>
        <origin rpy="0 0 0" xyz="0 0 0"/>
        <inertia ixx="0.003020299" ixy="0" ixz="0" iyy="0.0047175" iyz="0" izz="0.0076875"/>
      </inertial>
        <collision>
        <geometry>
          <box size="0.3 0.375 0.03"/>
        </geometry>
      </collision>
  </link>

    <gazebo reference="standoff_left_back">
      <material>Gazebo/Grey</material>
    </gazebo>

    <link name="standoff_left_back">
      <visual>
        <geometry>
          <cylinder length="0.3" radius="0.01"/>
        </geometry>
        <origin rpy="0 0 0" xyz="0 0 0"/>
        <material name="gray"/>
      </visual>
      <inertial>
        <mass value="0.1"/>
        <origin rpy="0 0 0" xyz="0 0 0"/>
        <inertia ixx="0.000752499999" ixy="0" ixz="0" iyy="0.000752499999" iyz="0" izz="0.000005"/>
      </inertial>
         <collision>
        <geometry>
          <cylinder length="0.3" radius="0.01"/>
        </geometry>
      </collision>
 </link>

    <gazebo reference="standoff_left_front">
      <material>Gazebo/Grey</material>
    </gazebo>

    <link name="standoff_left_front">
      <visual>
        <geometry>
          <cylinder length="0.3" radius="0.01"/>
        </geometry>
        <origin rpy="0 0 0" xyz="0 0 0"/>
        <material name="gray"/>
      </visual>
      <inertial>
        <mass value="0.1"/>
        <origin rpy="0 0 0" xyz="0 0 0"/>
        <inertia ixx="0.000752499999" ixy="0" ixz="0" iyy="0.000752499999" iyz="0" izz="0.000005"/>
      </inertial>
          <collision>
        <geometry>
          <cylinder length="0.3" radius="0.01"/>
        </geometry>
      </collision>
</link>

    <gazebo reference="standoff_right_back">
      <material>Gazebo/Grey</material>
    </gazebo>

    <link name="standoff_right_back">
      <visual>
        <geometry>
          <cylinder length="0.3" radius="0.01"/>
        </geometry>
        <origin rpy="0 0 0" xyz="0 0 0"/>
        <material name="gray"/>
      </visual>
      <inertial>
        <mass value="0.1"/>
        <origin rpy="0 0 0" xyz="0 0 0"/>
        <inertia ixx="0.000752499999" ixy="0" ixz="0" iyy="0.000752499999" iyz="0" izz="0.000005"/>
      </inertial>
       <collision>
        <geometry>
          <cylinder length="0.3" radius="0.01"/>
        </geometry>
      </collision>
   </link>

    <gazebo reference="standoff_right_front">
      <material>Gazebo/Grey</material>
    </gazebo>

    <link name="standoff_right_front">
      <visual>
        <geometry>
          <cylinder length="0.3" radius="0.01"/>
        </geometry>
        <origin rpy="0 0 0" xyz="0 0 0"/>
        <material name="gray"/>
      </visual>
      <inertial>
        <mass value="0.1"/>
        <origin rpy="0 0 0" xyz="0 0 0"/>
        <material name="gray"/>
        <inertia ixx="0.000752499999" ixy="0" ixz="0" iyy="0.000752499999" iyz="0" izz="0.000005"/>
      </inertial>
       <collision>
        <geometry>
          <cylinder length="0.3" radius="0.01"/>
        </geometry>
      </collision>
   </link>

    <gazebo reference="arm_baseplate">
      <material>Gazebo/Red</material>
    </gazebo>

    <link name="arm_baseplate">
      <visual>
        <geometry>
          <box size="0.45 0.65 0.03"/>
        </geometry>
        <origin rpy="0 0 0" xyz="0 0 0"/>
        <material name="red"/>
      </visual>
      <inertial>
        <mass value="0.5"/>
        <origin rpy="0 0 0" xyz="0 0 0"/>
        <inertia ixx="0.008475" ixy="0" ixz="0" iyy="0.01764166666" iyz="0" izz="0.026041666666"/>
      </inertial>
       <collision>
        <geometry>
          <box size="0.45 0.65 0.03"/>
        </geometry>
      </collision>
   </link>

    <gazebo reference="arm_lower_suppport">
      <material>Gazebo/Red</material>
    </gazebo>

    <link name="arm_lower_support">
      <visual>
        <geometry>
          <box size="0.2 0.4 0.03"/>
        </geometry>
        <origin rpy="1.5707 0 0" xyz="0 0 0"/>
        <material name="red"/>
      </visual>
      <inertial>
        <mass value="0.3"/>
        <origin rpy="1.5707 0 0" xyz="0 0 0"/>
        <inertia ixx="0.0010225" ixy="0" ixz="0" iyy="0.0040225" iyz="0" izz="0.005"/>
      </inertial>
       <collision>
        <origin rpy="1.5707 0 0" xyz="0 0 0"/>
        <geometry>
          <box size="0.2 0.4 0.03"/>
        </geometry>
      </collision>
   </link>

    <gazebo reference="arm_lower_motor">
      <material>Gazebo/Grey</material>
    </gazebo>

    <link name="arm_lower_motor">
      <visual>
        <geometry>
           <cylinder length="0.15" radius="0.075"/>
        </geometry>
        <origin rpy="1.5707 0 0" xyz="0 0 0"/>
        <material name="gray"/>
      </visual>
      <inertial>
        <mass value="0.5"/>
        <origin rpy="1.5707 0 0" xyz="0 0 0"/>
        <inertia ixx="0.001640625" ixy="0" ixz="0" iyy="0.001640625" iyz="0" izz="0.00140625"/>
      </inertial>
       <collision>
        <origin rpy="1.5707 0 0" xyz="0 0 0"/>
        <geometry>
           <cylinder length="0.15" radius="0.075"/>
        </geometry>
      </collision>
   </link>

    <gazebo reference="arm_lower_axel">
      <material>Gazebo/Blue</material>
    </gazebo>

    <link name="arm_lower_axel">
      <visual>
        <geometry>
           <cylinder length="0.1" radius="0.025"/>
        </geometry>
        <origin rpy="1.5707 0 0" xyz="0 0 0"/>
        <material name="blue"/>
      </visual>
      <inertial>
        <mass value="0.2"/>
        <origin rpy="1.5707 0 0" xyz="0 0 0"/>
        <inertia ixx="0.0001979166666" ixy="0" ixz="0" iyy="0.0001979166666" iyz="0" izz="0.0000625"/>
      </inertial>
       <collision>
        <origin rpy="1.5707 0 0" xyz="0 0 0"/>
        <geometry>
           <cylinder length="0.1" radius="0.025"/>
        </geometry>
      </collision>
   </link>

    <gazebo reference="arm_middle_support">
      <material>Gazebo/Red</material>
    </gazebo>

   <link name="arm_middle_support">
      <visual>
        <geometry>
          <box size="0.2 0.03 0.5"/>
        </geometry>
        <origin rpy="0 -0.39269 0" xyz="0 0 0"/>
        <material name="red"/>
      </visual>
      <inertial>
        <mass value="0.3"/>
        <origin rpy="0 -0.39269 0" xyz="0 0 0"/>
        <inertia ixx="0.00725" ixy="0" ixz="0" iyy="0.006272499999" iyz="0" izz="0.0010225"/>
      </inertial>
       <collision>
        <origin rpy="0 -0.39269 0" xyz="0 0 0"/>
        <geometry>
          <box size="0.2 0.03 0.5"/>
        </geometry>
      </collision>
   </link>

    <gazebo reference="arm_middle_motor">
      <material>Gazebo/Grey</material>
    </gazebo>

   <link name="arm_middle_motor">
      <visual>
        <geometry>
           <cylinder length="0.15" radius="0.075"/>
        </geometry>
        <origin rpy="1.5707 0 0" xyz="0 0 0"/>
        <material name="gray"/>
      </visual>
      <inertial>
        <mass value="0.5"/>
        <origin rpy="1.5707 0 0" xyz="0 0 0"/>
        <inertia ixx="0.001640625" ixy="0" ixz="0" iyy="0.001640625" iyz="0" izz="0.00140625"/>
      </inertial>
       <collision>
        <origin rpy="1.5707 0 0" xyz="0 0 0"/>
        <geometry>
           <cylinder length="0.15" radius="0.075"/>
        </geometry>
      </collision>
   </link>

    <gazebo reference="arm_middle_axel">
      <material>Gazebo/Blue</material>
    </gazebo>

    <link name="arm_middle_axel">
      <visual>
        <geometry>
           <cylinder length="0.1" radius="0.025"/>
        </geometry>
        <origin rpy="1.5707 0 0" xyz="0 0 0"/>
        <material name="blue"/>
      </visual>
      <inertial>
        <mass value="0.2"/>
        <origin rpy="1.5707 0 0" xyz="0 0 0"/>
        <inertia ixx="0.0001979166666" ixy="0" ixz="0" iyy="0.0001979166666" iyz="0" izz="0.0000625"/>
      </inertial>
       <collision>
        <origin rpy="1.5707 0 0" xyz="0 0 0"/>
        <geometry>
           <cylinder length="0.1" radius="0.025"/>
        </geometry>
      </collision>
   </link>

    <gazebo reference="arm_claw">
      <material>Gazebo/Red</material>
    </gazebo>

    <link name="arm_claw">
      <visual>
        <geometry>
          <box size="0.2 0.03 0.7"/>
        </geometry>
        <origin rpy="0 -0.36269 0" xyz="0 0 0"/>
        <material name="red"/>
      </visual>
      <inertial>
        <mass value="0.3"/>
        <origin rpy="0 -0.36269 0" xyz="0 0 0"/>
        <inertia ixx="0.01324999" ixy="0" ixz="0" iyy="0.0122724999" iyz="0" izz="0.0010225"/>
      </inertial>
       <collision>
        <origin rpy="0 -0.36269 0" xyz="0 0 0"/>
        <geometry>
          <box size="0.2 0.03 0.7"/>
        </geometry>
      </collision>
   </link>

    <gazebo reference="arm_hook">
      <material>Gazebo/Red</material>
    </gazebo>

    <link name="arm_hook">
      <visual>
        <geometry>
          <box size="0.2 0.03 0.05"/>
        </geometry>
        <origin rpy="0 2.7488 0" xyz="0 0 0"/>
        <material name="red"/>
      </visual>
      <inertial>
        <mass value="0.1"/>
        <origin rpy="0 2.7488 0" xyz="0 0 0"/>
        <inertia ixx="0.0003541666" ixy="0" ixz="0" iyy="0.00002833333" iyz="0" izz="0.0003408333333"/>
      </inertial>
       <collision>
        <origin rpy="0 2.7488 0" xyz="0 0 0"/>
        <geometry>
          <box size="0.2 0.03 0.05"/>
        </geometry>
      </collision>
   </link>


    <joint name="base_right_motor" type="fixed">
        <origin rpy="0 0 0" xyz="0.4 0.375 -0.1375"/>
        <parent link="base"/>
        <child link="right_wheel_motor"/>
    </joint>
    <joint name="right_wheel_and_axel" type="fixed">
        <origin rpy="0 0 0" xyz="0 0.15 0"/>
        <parent link="right_wheel_axel"/>
        <child link="right_wheel"/>
    </joint>
    <joint name="right_motor_and_axel" type="continuous">
        <origin rpy="0 0 0" xyz="0 0.075 0"/>
        <child link="right_wheel_axel"/>
        <parent link="right_wheel_motor"/>
        <axis xyz="0 1 0"/>
    </joint>
    <joint name="right_wheel_and_indicator" type="fixed">
        <origin rpy="0 0 0" xyz="0 0.05 0.15"/>
        <parent link="right_wheel"/>
        <child link="right_wheel_spin_indicator"/>
    </joint>
    <joint name="base_left_motor" type="fixed">
        <origin rpy="0 0 0" xyz="0.4 -0.375 -0.1375"/>
        <parent link="base"/>
        <child link="left_wheel_motor"/>
    </joint>
    <joint name="left_wheel_and_axel" type="fixed">
        <origin rpy="0 0 0" xyz="0 -0.15 0"/>
        <parent link="left_wheel_axel"/>
        <child link="left_wheel"/>
    </joint>
    <joint name="left_motor_and_axel" type="continuous">
        <origin rpy="0 0 0" xyz="0 -0.075 0"/>
        <child link="left_wheel_axel"/>
        <parent link="left_wheel_motor"/>
        <axis xyz="0 1 0"/>
    </joint>
    <joint name="left_wheel_and_indicator" type="fixed">
        <origin rpy="0 0 0" xyz="0 -0.05 0.15"/>
        <parent link="left_wheel"/>
        <child link="left_wheel_spin_indicator"/>
    </joint>
    <joint name="base_right_caster_shaft" type="fixed">
        <origin rpy="0 0 0" xyz="-0.5 -0.25 -0.15"/>
        <child link="right_caster_shaft"/>
        <parent link="base"/>
    </joint>
    <joint name="right_caster_shaft_ball" type="fixed">
        <origin rpy="0 0 0" xyz="0 0 -0.15"/>
        <parent link="right_caster_shaft"/>
        <child link="right_caster_ball"/>
    </joint>
    <joint name="base_left_caster_shaft" type="fixed">
        <origin rpy="0 0 0" xyz="-0.5 0.25 -0.15"/>
        <child link="left_caster_shaft"/>
        <parent link="base"/>
    </joint>
    <joint name="left_caster_shaft_ball" type="fixed">
        <origin rpy="0 0 0" xyz="0 0 -0.15"/>
        <parent link="left_caster_shaft"/>
        <child link="left_caster_ball"/>
    </joint>
    <joint name="base_screen_mount" type="fixed">
        <origin rpy="0 0 0" xyz="-0.5 0 0.3"/>
        <parent link="base"/>
        <child link="screen_mount"/>
    </joint>
    <joint name="screen_mount_screen" type="fixed">
        <origin rpy="0 0 0" xyz="0 0 0.27"/>
        <parent link="screen_mount"/>
        <child link="screen"/>
    </joint>
    <joint name="base_computer_base" type="fixed">
        <origin rpy="0 0 0" xyz="0.1 -0.25 0.07"/>
        <parent link="base"/>
        <child link="computer_baseplate"/>
    </joint>
    <joint name="computer_base_board_low" type="fixed">
        <origin rpy="0 0 0" xyz="0 0 0.105"/>
        <parent link="computer_baseplate"/>
        <child link="board_low"/>
    </joint>
    <joint name="computer_base_board_high" type="fixed">
        <origin rpy="0 0 0" xyz="0 0 0.23"/>
        <parent link="computer_baseplate"/>
        <child link="board_high"/>
    </joint>
    <joint name="computer_base_standoff_left_back" type="fixed">
        <origin rpy="0 0 0" xyz="0.125 0.16 0.13"/>
        <parent link="computer_baseplate"/>
        <child link="standoff_left_back"/>
    </joint>
    <joint name="computer_base_standoff_left_front" type="fixed">
        <origin rpy="0 0 0" xyz="-0.125 0.16 0.13"/>
        <parent link="computer_baseplate"/>
        <child link="standoff_left_front"/>
    </joint>
    <joint name="computer_base_standoff_right_front" type="fixed">
        <origin rpy="0 0 0" xyz="-0.125 -0.16 0.13"/>
        <parent link="computer_baseplate"/>
        <child link="standoff_right_front"/>
    </joint>
    <joint name="computer_base_standoff_right_back" type="fixed">
        <origin rpy="0 0 0" xyz="0.125 -0.16 0.13"/>
        <parent link="computer_baseplate"/>
        <child link="standoff_right_back"/>
    </joint>
    <joint name="base_arm_base" type="fixed">
        <origin rpy="0 0 0" xyz="0.525 0 0.07"/>
        <parent link="base"/>
        <child link="arm_baseplate"/>
    </joint>
    <joint name="arm_base_lower_support" type="fixed">
        <origin rpy="0 0 0" xyz="0 0 0.205"/>
        <parent link="arm_baseplate"/>
        <child link="arm_lower_support"/>
    </joint>
    <joint name="arm_support_lower_motor" type="fixed">
        <origin rpy="0 0 0" xyz="0 0.075 0.1"/>
        <parent link="arm_lower_support"/>
        <child link="arm_lower_motor"/>
    </joint>
    <joint name="arm_support_lower_lower_axel" type="continuous">
        <origin rpy="0 0 0" xyz="0 0 0.1"/>
        <parent link="arm_lower_support"/>
        <child link="arm_lower_axel"/>
        <axis xyz="0 1 0"/>
    </joint>
    <joint name="arm_lower_axel_middle_support" type="fixed">
        <origin rpy="0 0 0" xyz="-0.05 -0.05 0.175"/>
        <parent link="arm_lower_axel"/>
        <child link="arm_middle_support"/>
    </joint>
    <joint name="arm_middle_support_middle_motor" type="fixed">
        <origin rpy="0 0 0" xyz="-0.05 0.0625 0.125"/>
        <parent link="arm_middle_support"/>
        <child link="arm_middle_motor"/>
    </joint>
    <joint name="arm_middle_support_middle_axel" type="continuous">
        <origin rpy="0 0 0" xyz="-0.05 0 0.125"/>
        <parent link="arm_middle_support"/>
        <child link="arm_middle_axel"/>
        <axis xyz="0 1 0"/>
    </joint>
    <joint name="arm_middle_axel_claw" type="fixed">
        <origin rpy="0 0 0" xyz="0.0925 -0.05 -0.215"/>
        <parent link="arm_middle_axel"/>
        <child link="arm_claw"/>
    </joint>
    <joint name="arm_claw_hook" type="fixed">
        <origin rpy="0 0 0" xyz="0.2325 0 -0.255"/>
        <parent link="arm_claw"/>
        <child link="arm_hook"/>
    </joint>


    <transmission name="right_motor_and_axel_trans">
        <type>transmission_interface/SimpleTransmission</type>
        <joint name="right_motor_and_axel">
          <hardwareInterface>hardware_interface/VelocityJointInterface</hardwareInterface>
        </joint>
        <actuator name="motor1">
            <hardwareInterface>hardware_interface/VelocityJointInterface</hardwareInterface>
            <mechanicalReduction>1</mechanicalReduction>
        </actuator>
    </transmission>
    <transmission name="left_motor_and_axel_trans">
        <type>transmission_interface/SimpleTransmission</type>
        <joint name="left_motor_and_axel">
          <hardwareInterface>hardware_interface/VelocityJointInterface</hardwareInterface>
        </joint>
        <actuator name="motor2">
          <hardwareInterface>hardware_interface/VelocityJointInterface</hardwareInterface>
          <mechanicalReduction>1</mechanicalReduction>
        </actuator>
    </transmission>

</robot>
